Workbook

Sheet Lev.Quadros
A2: Concat. | B2: DESCRIÇÃO | C2: Nova TAG | D2: PAI | E2: PAVIMENTO | F2: SISTEMA | G2: SITUAÇÃO | H2: LOCAL | I2: <=Link | J2: Foto360 | K2: Proj. Quadros | L2: Projetos Quadros Executivos | M2: Pin. | N2: Foto.Quadro | O2: TIPO | P2: OBS: | Q2: id | R2: x_planta | S2: y_planta | T2: x_3d | U2: y_3d | V2: z_3d
A3: =CONCATENATE(H3,"-",B3) -> TJ-04º Pav.-Sala Elétrica E2-3QD-E3 | B3: 3QD-E3 | C3: QDEC-12E3 | E3: 4º Pav. | F3: Elétrica | G3: Existente | H3: TJ-04º Pav.-Sala Elétrica E2 | J3: =HYPERLINK( VLOOKUP(H3,'Localização'!A3:K39,9),"<=Link") -> <=Link
A4: =CONCATENATE(H4,"-",B4) -> TJ-04º Pav.-Sala Elétrica E3- | C4: QDEC-13E3 | E4: 4º Pav. | F4: Elétrica | G4: Existente | H4: TJ-04º Pav.-Sala Elétrica E3 | J4: =HYPERLINK( VLOOKUP(H4,'Localização'!A4:K39,9),"<=Link") -> <=Link
A5: =CONCATENATE(H5,"-",B5) -> TJ-04º Pav.-Sala Elétrica W2- | C5: QDEE-12E3 | E5: 4º Pav. | F5: Elétrica | G5: Existente | H5: TJ-04º Pav.-Sala Elétrica W2 | J5: =HYPERLINK( VLOOKUP(H5,'Localização'!A5:K39,9),"<=Link") -> <=Link
A6: =CONCATENATE(H6,"-",B6) -> TJ-04º Pav.-Sala Elétrica W3- | C6: QDI-12E3 | E6: 4º Pav. | F6: Elétrica | G6: Existente | H6: TJ-04º Pav.-Sala Elétrica W3 | J6: =HYPERLINK( VLOOKUP(H6,'Localização'!A6:K39,9),"<=Link") -> <=Link
A7: =CONCATENATE(H7,"-",B7) -> TJ-12º Pav.-Sala Elétrica E2-QDEC-12E2 | B7: QDEC-12E2 | E7: 12º Pav. | F7: Elétrica | G7: Novo | H7: TJ-12º Pav.-Sala Elétrica E2 | J7: =HYPERLINK( VLOOKUP(H7,'Localização'!A7:K39,9),"<=Link") -> <=Link | L7: 08421 - QDEC-12E2.pdf
A8: =CONCATENATE(H8,"-",B8) -> TJ-12º Pav.-Sala Elétrica E2-QDEE-12E2 | B8: QDEE-12E2 | E8: 12º Pav. | F8: Elétrica | G8: Novo | H8: TJ-12º Pav.-Sala Elétrica E2 | J8: =HYPERLINK( VLOOKUP(H8,'Localização'!A8:K39,9),"<=Link") -> <=Link | L8: 09021 - QDEE-12E2.pdf
A9: =CONCATENATE(H9,"-",B9) -> TJ-12º Pav.-Sala Elétrica E2-QDI-12E2 | B9: QDI-12E2 | E9: 12º Pav. | F9: Elétrica | G9: Novo | H9: TJ-12º Pav.-Sala Elétrica E2 | J9: =HYPERLINK( VLOOKUP(H9,'Localização'!A9:K39,9),"<=Link") -> <=Link | L9: 07821 - QDI-12E2.pdf
A10: =CONCATENATE(H10,"-",B10) -> TJ-12º Pav.-Sala Elétrica E3-QDEC-12E3 | B10: QDEC-12E3 | E10: 12º Pav. | F10: Elétrica | G10: Novo | H10: TJ-12º Pav.-Sala Elétrica E3 | J10: =HYPERLINK( VLOOKUP(H10,'Localização'!A10:K39,9),"<=Link") -> <=Link | L10: 08521 - QDEC-12E3.pdf
A11: =CONCATENATE(H11,"-",B11) -> TJ-12º Pav.-Sala Elétrica E3-QDEC-13E3 | B11: QDEC-13E3 | E11: 13º Pav. | F11: Elétrica | G11: Novo | H11: TJ-12º Pav.-Sala Elétrica E3 | J11: =HYPERLINK( VLOOKUP(H11,'Localização'!A11:K39,9),"<=Link") -> <=Link | L11: 08921 - QDEC-13E3.pdf
A12: =CONCATENATE(H12,"-",B12) -> TJ-12º Pav.-Sala Elétrica E3-QDEE-12E3 | B12: QDEE-12E3 | E12: 12º Pav. | F12: Elétrica | G12: Novo | H12: TJ-12º Pav.-Sala Elétrica E3 | J12: =HYPERLINK( VLOOKUP(H12,'Localização'!A12:K39,9),"<=Link") -> <=Link | L12: 09521 - QDEE-12E3.pdf
A13: =CONCATENATE(H13,"-",B13) -> TJ-12º Pav.-Sala Elétrica E3-QDI-12E3 | B13: QDI-12E3 | E13: 12º Pav. | F13: Elétrica | G13: Novo | H13: TJ-12º Pav.-Sala Elétrica E3 | J13: =HYPERLINK( VLOOKUP(H13,'Localização'!A13:K39,9),"<=Link") -> <=Link | L13: 08021 - QDI-12E3.pdf
A14: =CONCATENATE(H14,"-",B14) -> TJ-12º Pav.-Sala Elétrica W2-QDEC-12W2 | B14: QDEC-12W2 | E14: 12º Pav. | F14: Elétrica | G14: Novo | H14: TJ-12º Pav.-Sala Elétrica W2 | J14: =HYPERLINK( VLOOKUP(H14,'Localização'!A14:K39,9),"<=Link") -> <=Link | L14: 08621 - QDEC-12W2.pdf | R14: 120 | S14: 120 | T14: -4 | U14: 3 | V14: 2
A15: =CONCATENATE(H15,"-",B15) -> TJ-12º Pav.-Sala Elétrica W2-QDEE-12W2 | B15: QDEE-12W2 | E15: 12º Pav. | F15: Elétrica | G15: Novo | H15: TJ-12º Pav.-Sala Elétrica W2 | J15: =HYPERLINK( VLOOKUP(H15,'Localização'!A15:K39,9),"<=Link") -> <=Link | L15: 09121 - QDEE-12W2.pdf | R15: 120 | S15: 120 | T15: -2 | U15: 3 | V15: 2
A16: =CONCATENATE(H16,"-",B16) -> TJ-12º Pav.-Sala Elétrica W2-QDI-12W2 | B16: QDI-12W2 | E16: 12º Pav. | F16: Elétrica | G16: Novo | H16: TJ-12º Pav.-Sala Elétrica W2 | J16: =HYPERLINK( VLOOKUP(H16,'Localização'!A16:K39,9),"<=Link") -> <=Link | L16: 08121 - QDI-12W2.pdf | R16: 120 | S16: 120 | T16: -1 | U16: 5 | V16: 2
A17: =CONCATENATE(H17,"-",B17) -> TJ-12º Pav.-Sala Elétrica W2-QDEC-12W2 | B17: QDEC-12W2 | E17: 12º Pav. | F17: Elétrica | G17: Novo | H17: TJ-12º Pav.-Sala Elétrica W2 | J17: =HYPERLINK( VLOOKUP(H17,'Localização'!A17:K39,9),"<=Link") -> <=Link | R17: 120 | S17: 120 | T17: -8 | U17: 3 | V17: 2
A18: =CONCATENATE(H18,"-",B18) -> TJ-12º Pav.-Sala Elétrica W3-QDEC-12W3 | B18: QDEC-12W3 | E18: 12º Pav. | F18: Elétrica | G18: Novo | H18: TJ-12º Pav.-Sala Elétrica W3 | J18: =HYPERLINK( VLOOKUP(H18,'Localização'!A17:K39,9),"<=Link") -> <=Link | L18: 08721 - QDEC-12W3.pdf | R18: 120 | S18: 120 | T18: -8 | U18: 3 | V18: 2
A19: =CONCATENATE(H19,"-",B19) -> TJ-12º Pav.-Sala Elétrica W3-QDEE-12W3 | B19: QDEE-12W3 | E19: 12º Pav. | F19: Elétrica | G19: Novo | H19: TJ-12º Pav.-Sala Elétrica W3 | J19: =HYPERLINK( VLOOKUP(H19,'Localização'!A18:K39,9),"<=Link") -> <=Link | L19: 09321 - QDEE-12W3.pdf | R19: 120 | S19: 120 | T19: -8 | U19: 3 | V19: 2
A20: =CONCATENATE(H20,"-",B20) -> TJ-12º Pav.-Sala Elétrica W3-QDI-12W3 | B20: QDI-12W3 | E20: 12º Pav. | F20: Elétrica | G20: Novo | H20: TJ-12º Pav.-Sala Elétrica W3 | J20: =HYPERLINK( VLOOKUP(H20,'Localização'!A19:K39,9),"<=Link") -> <=Link | L20: 07921 - QDI-12W3.pdf | R20: 120 | S20: 120 | T20: -8 | U20: 3 | V20: 2
A21: =CONCATENATE(H21,"-",B21) -> TJ-13º Pav.-Sala Elétrica E3-QDEE-13E3 | B21: QDEE-13E3 | E21: 13º Pav. | F21: Elétrica | G21: Novo | H21: TJ-13º Pav.-Sala Elétrica E3 | J21: =HYPERLINK( VLOOKUP(H21,'Localização'!A20:K39,9),"<=Link") -> <=Link | L21: 09421 - QDEE-13E3.pdf | R21: 120 | S21: 120 | T21: -8 | U21: 3 | V21: 2
A22: =CONCATENATE(H22,"-",B22) -> TJ-13º Pav.-Sala Elétrica E3-QDI-13E3 | B22: QDI-13E3 | E22: 13º Pav. | F22: Elétrica | G22: Novo | H22: TJ-13º Pav.-Sala Elétrica E3 | J22: =HYPERLINK( VLOOKUP(H22,'Localização'!A21:K39,9),"<=Link") -> <=Link | L22: 08221 - QDI-13E3.pdf | R22: 120 | S22: 120 | T22: -8 | U22: 5 | V22: 2
A23: =CONCATENATE(H23,"-",B23) -> TJ-13º Pav.-Sala Elétrica W3-QDEC-13W3 | B23: QDEC-13W3 | E23: 13º Pav. | F23: Elétrica | G23: Novo | H23: TJ-13º Pav.-Sala Elétrica W3 | J23: =HYPERLINK( VLOOKUP(H23,'Localização'!A22:K39,9),"<=Link") -> <=Link | L23: 08821 - QDEC-13W3.pdf | R23: 120 | S23: 120 | T23: -8 | U23: 3 | V23: 2
A24: =CONCATENATE(H24,"-",B24) -> TJ-13º Pav.-Sala Elétrica W3-QDEE-13W3 | B24: QDEE-13W3 | E24: 13º Pav. | F24: Elétrica | G24: Novo | H24: TJ-13º Pav.-Sala Elétrica W3 | J24: =HYPERLINK( VLOOKUP(H24,'Localização'!A23:K39,9),"<=Link") -> <=Link | L24: 09221 - QDEE-13W3.pdf | R24: 120 | S24: 120 | T24: -8 | U24: 3 | V24: 2
A25: =CONCATENATE(H25,"-",B25) -> TJ-13º Pav.-Sala Elétrica W3-QDI-13W3 | B25: QDI-13W3 | E25: 13º Pav. | F25: Elétrica | G25: Novo | H25: TJ-13º Pav.-Sala Elétrica W3 | J25: =HYPERLINK( VLOOKUP(H25,'Localização'!A24:K39,9),"<=Link") -> <=Link | L25: 08321 - QDI-13W3.pdf | R25: 120 | S25: 120 | T25: -8 | U25: 3 | V25: 2
A26: =CONCATENATE(H26,"-",B26) -> TJ.ANX-Térreo--Quadro CD-C1SS1.pdf | B26: Quadro CD-C1SS1.pdf | E26: Térro | F26: Elétrica | G26: Novo | H26: TJ.ANX-Térreo- | J26: =HYPERLINK( VLOOKUP(H26,'Localização'!A25:K39,9),"<=Link") -> <=Link | R26: 120 | S26: 120 | T26: -8 | U26: 3 | V26: 2
A27: =CONCATENATE(H27,"-",B27) -> TJ.ANX-Térreo--Quadro CD-C1SS2.pdf | B27: Quadro CD-C1SS2.pdf | E27: Térro | F27: Elétrica | G27: Novo | H27: TJ.ANX-Térreo- | J27: =HYPERLINK( VLOOKUP(H27,'Localização'!A26:K39,9),"<=Link") -> <=Link | R27: 120 | S27: 120 | T27: -8 | U27: 3 | V27: 2
A28: =CONCATENATE(H28,"-",B28) -> TJ.ANX-Térreo--Quadro CD-C2P1.pdf | B28: Quadro CD-C2P1.pdf | E28: Térro | F28: Elétrica | G28: Novo | H28: TJ.ANX-Térreo- | J28: =HYPERLINK( VLOOKUP(H28,'Localização'!A27:K39,9),"<=Link") -> <=Link | R28: 120 | S28: 120 | T28: -8 | U28: 5 | V28: 2
A29: =CONCATENATE(H29,"-",B29) -> TJ.ANX-Térreo--Quadro CD-C2P2.pdf | B29: Quadro CD-C2P2.pdf | E29: Térro | F29: Elétrica | G29: Novo | H29: TJ.ANX-Térreo- | J29: =HYPERLINK( VLOOKUP(H29,'Localização'!A28:K39,9),"<=Link") -> <=Link | R29: 120 | S29: 120 | T29: -8 | U29: 3 | V29: 2
A30: =CONCATENATE(H30,"-",B30) -> TJ.ANX-Térreo--Quadro CD-C2SS1.pdf | B30: Quadro CD-C2SS1.pdf | E30: Térro | F30: Elétrica | G30: Novo | H30: TJ.ANX-Térreo- | J30: =HYPERLINK( VLOOKUP(H30,'Localização'!A29:K39,9),"<=Link") -> <=Link | R30: 120 | S30: 120 | T30: -8 | U30: 3 | V30: 2
A31: =CONCATENATE(H31,"-",B31) -> TJ.ANX-Térreo--Quadro CD-C2SS2.pdf | B31: Quadro CD-C2SS2.pdf | E31: Térro | F31: Elétrica | G31: Novo | H31: TJ.ANX-Térreo- | J31: =HYPERLINK( VLOOKUP(H31,'Localização'!A30:K39,9),"<=Link") -> <=Link | R31: 120 | S31: 120 | T31: -8 | U31: 5 | V31: 2
A32: =CONCATENATE(H32,"-",B32) -> TJ.ANX-Térreo--Quadro CD-C3SS1.pdf | B32: Quadro CD-C3SS1.pdf | E32: Térro | F32: Elétrica | G32: Novo | H32: TJ.ANX-Térreo- | J32: =HYPERLINK( VLOOKUP(H32,'Localização'!A31:K39,9),"<=Link") -> <=Link | R32: 120 | S32: 120 | T32: -8 | U32: 3 | V32: 2
A33: =CONCATENATE(H33,"-",B33) -> TJ.ANX-Térreo--Quadro CD-C3SS2.pdf | B33: Quadro CD-C3SS2.pdf | E33: Térro | F33: Elétrica | G33: Novo | H33: TJ.ANX-Térreo- | J33: =HYPERLINK( VLOOKUP(H33,'Localização'!A32:K39,9),"<=Link") -> <=Link | R33: 120 | S33: 120 | T33: -8 | U33: 3 | V33: 2
A34: =CONCATENATE(H34,"-",B34) -> TJ.ANX-Térreo--Quadro CD-CTE1.pdf | B34: Quadro CD-CTE1.pdf | E34: Térro | F34: Elétrica | G34: Novo | H34: TJ.ANX-Térreo- | J34: =HYPERLINK( VLOOKUP(H34,'Localização'!A33:K39,9),"<=Link") -> <=Link | R34: 120 | S34: 120 | T34: -8 | U34: 5 | V34: 2
A35: =CONCATENATE(H35,"-",B35) -> TJ.ANX-Térreo--Quadro CD-CTE2.pdf | B35: Quadro CD-CTE2.pdf | E35: Térro | F35: Elétrica | G35: Novo | H35: TJ.ANX-Térreo- | J35: =HYPERLINK( VLOOKUP(H35,'Localização'!A34:K39,9),"<=Link") -> <=Link | R35: 120 | S35: 120 | T35: -8 | U35: 3 | V35: 2
A36: =CONCATENATE(H36,"-",B36) -> TJ.ANX-Térreo--Quadro CD-ETE1.pdf | B36: Quadro CD-ETE1.pdf | E36: Térro | F36: Elétrica | G36: Novo | H36: TJ.ANX-Térreo- | J36: =HYPERLINK( VLOOKUP(H36,'Localização'!A35:K39,9),"<=Link") -> <=Link | R36: 120 | S36: 120 | T36: -8 | U36: 2 | V36: 2
A37: =CONCATENATE(H37,"-",B37) -> TJ.ANX-Térreo--Quadro CD-ETE2.pdf | B37: Quadro CD-ETE2.pdf | E37: Térro | F37: Elétrica | G37: Novo | H37: TJ.ANX-Térreo- | J37: =HYPERLINK( VLOOKUP(H37,'Localização'!A36:K39,9),"<=Link") -> <=Link | R37: 120 | S37: 120 | T37: -8 | U37: 2 | V37: 2
A38: =CONCATENATE(H38,"-",B38) -> TJ.ANX-Térreo--Quadro QG-ESTAC-NORTE.pdf | B38: Quadro QG-ESTAC-NORTE.pdf | E38: Térro | F38: Elétrica | G38: Novo | H38: TJ.ANX-Térreo- | J38: =HYPERLINK( VLOOKUP(H38,'Localização'!A37:K39,9),"<=Link") -> <=Link | R38: 120 | S38: 120 | T38: -5 | U38: 2 | V38: 2
A39: =CONCATENATE(H39,"-",B39) -> TJ.ANX-Térreo--Quadro QG-ESTAC-SUL.pdf | B39: Quadro QG-ESTAC-SUL.pdf | E39: Térro | F39: Elétrica | G39: Novo | H39: TJ.ANX-Térreo- | J39: =HYPERLINK( VLOOKUP(H39,'Localização'!A38:K39,9),"<=Link") -> <=Link | R39: 120 | S39: 120 | T39: -8 | U39: 2 | V39: 2

Sheet Plan1
B1: PAVIMENTO | C1: QTDE (uni) | F1: QUADRO FANCOILS | K1: QUADRO EXAUSTORES
B2: Térreo | C2: =COUNTIF(Lev.Quadros!$E$3:$E$23,B2) -> 0 | F2: PAVIMENTO | G2: QTDE (uni) | H2: INSTALADOS | I2: PERCENTUAL | K2: PAVIMENTO | L2: QTDE (uni) | M2: INSTALADOS | N2: PERCENTUAL
B3: Mezanino | C3: =COUNTIF(Lev.Quadros!$E$3:$E$23,B3) -> 0 | F3: Mezanino | G3: =COUNTIFS(Lev.Quadros!$E$3:$E$23,F3,#REF!,"fancoil") -> #VALUE! | I3: =H3/G3 -> #VALUE! | K3: Térreo | L3: =COUNTIFS(Lev.Quadros!$E$3:$E$23,K3,#REF!,"exaustores") -> #VALUE!
B4: 2º Pavimento | C4: =COUNTIF(Lev.Quadros!$E$3:$E$23,B4) -> 0 | F4: 2º Pavimento | G4: =COUNTIFS(Lev.Quadros!$E$3:$E$23,F4,#REF!,"fancoil") -> #VALUE! | I4: =H4/G4 -> #VALUE! | K4: Mezanino | L4: =COUNTIFS(Lev.Quadros!$E$3:$E$23,K4,#REF!,"exaustores") -> #VALUE! | N4: =M4/L4 -> #VALUE!
B5: 3º Pavimento | C5: =COUNTIF(Lev.Quadros!$E$3:$E$23,B5) -> 0 | F5: 3º Pavimento | G5: =COUNTIFS(Lev.Quadros!$E$3:$E$23,F5,#REF!,"fancoil") -> #VALUE! | I5: =H5/G5 -> #VALUE! | K5: 2º Pavimento | L5: =COUNTIFS(Lev.Quadros!$E$3:$E$23,K5,#REF!,"exaustores") -> #VALUE! | N5: =M5/L5 -> #VALUE!
B6: 4º Pavimento | C6: =COUNTIF(Lev.Quadros!$E$3:$E$23,B6) -> 0 | F6: 4º Pavimento | G6: =COUNTIFS(Lev.Quadros!$E$3:$E$23,F6,#REF!,"fancoil") -> #VALUE! | I6: =H6/G6 -> #VALUE! | K6: 3º Pavimento | L6: =COUNTIFS(Lev.Quadros!$E$3:$E$23,K6,#REF!,"exaustores") -> #VALUE! | N6: =M6/L6 -> #VALUE!
B7: 5º Pavimento | C7: =COUNTIF(Lev.Quadros!$E$3:$E$23,B7) -> 0 | F7: 5º Pavimento | G7: =COUNTIFS(Lev.Quadros!$E$3:$E$23,F7,#REF!,"fancoil") -> #VALUE! | I7: =H7/G7 -> #VALUE! | K7: 4º Pavimento | L7: =COUNTIFS(Lev.Quadros!$E$3:$E$23,K7,#REF!,"exaustores") -> #VALUE! | N7: =M7/L7 -> #VALUE!
B8: 6º Pavimento | C8: =COUNTIF(Lev.Quadros!$E$3:$E$23,B8) -> 0 | F8: 6º Pavimento | G8: =COUNTIFS(Lev.Quadros!$E$3:$E$23,F8,#REF!,"fancoil") -> #VALUE! | I8: =H8/G8 -> #VALUE! | K8: 5º Pavimento | L8: =COUNTIFS(Lev.Quadros!$E$3:$E$23,K8,#REF!,"exaustores") -> #VALUE! | N8: =M8/L8 -> #VALUE!
B9: Cobertura | C9: =COUNTIF(Lev.Quadros!$E$3:$E$23,B9) -> 0 | F9: Cobertura | G9: =COUNTIFS(Lev.Quadros!$E$3:$E$23,F9,#REF!,"fancoil") -> #VALUE! | I9: =H9/G9 -> #VALUE! | K9: 6º Pavimento | L9: =COUNTIFS(Lev.Quadros!$E$3:$E$23,K9,#REF!,"exaustores") -> #VALUE! | N9: =M9/L9 -> #VALUE!
B10: TOTAL | C10: =SUM(C2:C9) -> 0 | F10: TOTAL | G10: =SUM(G3:G9) -> #VALUE! | H10: =SUM(H3:H9) -> 0 | I10: =H10/G10 -> #VALUE! | K10: Cobertura | L10: =COUNTIFS(Lev.Quadros!$E$3:$E$23,K10,#REF!,"exaustores") -> #VALUE! | N10: =M10/L10 -> #VALUE!
K11: TOTAL | L11: =SUM(L4:L10) -> #VALUE! | M11: =SUM(M4:M10) -> 0 | N11: =M11/L11 -> #VALUE!

Sheet RELATÓRIO
B2: RELATÓRIO DE QUADROS
B3: DATA | C3: =TODAY() -> 46195
B6: COMANDO | H6: DISTRIBUIÇÃO
B8: APROVAÇÃO | F8: =SUMIFS(#REF!,#REF!,"APROVADO",Lev.Quadros!$O$3:$O$23,"COMANDO") -> #N/A | H8: APROVAÇÃO | L8: =SUMIFS(#REF!,#REF!,"APROVADO",Lev.Quadros!$O$3:$O$23,"DISTRIBUIÇÃO") -> #N/A
B9: NÃO APROVAÇÃO | F9: =SUMIFS(#REF!,#REF!,"NÃO APROVADO",Lev.Quadros!$O$3:$O$23,"COMANDO") -> #N/A | H9: NÃO APROVAÇÃO | L9: =SUMIFS(#REF!,#REF!,"NÃO APROVADO",Lev.Quadros!$O$3:$O$23,"DISTRIBUIÇÃO") -> #N/A
B10: EM ANÁLISE | F10: =SUMIFS(#REF!,#REF!,"EM ANÁLISE",Lev.Quadros!$O$3:$O$23,"COMANDO") -> #N/A | H10: EM ANÁLISE | L10: =SUMIFS(#REF!,#REF!,"EM ANÁLISE",Lev.Quadros!$O$3:$O$23,"DISTRIBUIÇÃO") -> #N/A
F11: =SUM(F8:F10) -> #N/A | L11: =SUM(L8:L10) -> #N/A
B29: NÃO APROVADOS | H29: NÃO APROVADOS
B31: APROVADO PARA FABRICAÇÃO | F31: =SUMIFS(#REF!,Lev.Quadros!$O$3:$O$23,"COMANDO",#REF!,"NÃO APROVADO",#REF!,"APROVADO PARA FABRICAÇÃO") -> #N/A | H31: APROVADO PARA FABRICAÇÃO | L31: =SUMIFS(#REF!,#REF!,"DISTRIBUIÇÃO",#REF!,"NÃO APROVADO",#REF!,"APROVADO PARA FABRICAÇÃO") -> #N/A
B32: CORREÇÃO PROJETO EXECUTIVO | F32: =SUMIFS(#REF!,Lev.Quadros!$O$3:$O$23,"COMANDO",#REF!,"NÃO APROVADO",#REF!,"CORREÇÃO PROJETO EXECUTIVO") -> #N/A | H32: CORREÇÃO PROJETO EXECUTIVO | L32: =SUMIFS(#REF!,#REF!,"DISTRIBUIÇÃO",#REF!,"NÃO APROVADO",#REF!,"CORREÇÃO PROJETO EXECUTIVO") -> #N/A
B33: ENVIADO GHC | F33: =SUMIFS(#REF!,#REF!,"COMANDO",#REF!,"NÃO APROVADO",#REF!,"ENVIADO GHC") -> #N/A | H33: ENVIADO GHC | L33: =SUMIFS(#REF!,#REF!,"DISTRIBUIÇÃO",#REF!,"NÃO APROVADO",#REF!,"ENVIADO GHC") -> #N/A

Sheet Localização
A2: NomeConc. | B2: Pavimento | C2: 2ºPav. | D2: Parent | E2: Setor | F2: Pin | G2: Link | H2: Tipo | I2: Foto360º | J2: Porta | K2: Observações
A3: =CONCATENATE(B3,"-",C3) -> TJ-02º Pav.- | B3: TJ-02º Pav.
A4: =CONCATENATE(B4,"-",C4) -> TJ-02º Pav.-Sala Elétrica E2 | B4: TJ-02º Pav. | C4: Sala Elétrica E2 | E4: E2
A5: =CONCATENATE(B5,"-",C5) -> TJ-02º Pav.-Sala Elétrica E3 | B5: TJ-02º Pav. | C5: Sala Elétrica E3 | E5: E3
A6: =CONCATENATE(B6,"-",C6) -> TJ-02º Pav.-Sala Elétrica W2 | B6: TJ-02º Pav. | C6: Sala Elétrica W2 | E6: W2
A7: =CONCATENATE(B7,"-",C7) -> TJ-02º Pav.-Sala Elétrica W3 | B7: TJ-02º Pav. | C7: Sala Elétrica W3 | E7: W3
A8: =CONCATENATE(B8,"-",C8) -> TJ-03º Pav.- | B8: TJ-03º Pav.
A9: =CONCATENATE(B9,"-",C9) -> TJ-03º Pav.-Sala Elétrica E2 | B9: TJ-03º Pav. | C9: Sala Elétrica E2 | E9: E2
A10: =CONCATENATE(B10,"-",C10) -> TJ-03º Pav.-Sala Elétrica E3 | B10: TJ-03º Pav. | C10: Sala Elétrica E3 | E10: E3
A11: =CONCATENATE(B11,"-",C11) -> TJ-03º Pav.-Sala Elétrica W2 | B11: TJ-03º Pav. | C11: Sala Elétrica W2 | E11: W2
A12: =CONCATENATE(B12,"-",C12) -> TJ-03º Pav.-Sala Elétrica W3 | B12: TJ-03º Pav. | C12: Sala Elétrica W3 | E12: W3
A13: =CONCATENATE(B13,"-",C13) -> TJ-04º Pav.- | B13: TJ-04º Pav.
A14: =CONCATENATE(B14,"-",C14) -> TJ-04º Pav.-Sala Elétrica E2 | B14: TJ-04º Pav. | C14: Sala Elétrica E2 | E14: E2 | I14: https://photos.google.com/album/AF1QipNJAaZMyYxPFzC78T6Y7KRZc2jtSwC35HdfZPQd/photo/AF1QipOAs8tp3if3M89jdYr1XG_Uwgur02SOwXk4o86D
A15: =CONCATENATE(B15,"-",C15) -> TJ-04º Pav.-Sala Elétrica E3 | B15: TJ-04º Pav. | C15: Sala Elétrica E3 | E15: E3 | I15: https://photos.google.com/share/AF1QipPeNmAmLKZb5OwnD_ZCxO-oLVMAaoDVbiZEgKo9SEIldj0JatgswpGx7D4QwNtplg/photo/AF1QipMggUmuaHkE6oLyGCiZ7QFPzYEN7StmiaMinBbh?key=R1RyWjFkWDNIV2VlUXkzb0VuT0FyVHFWRkl1emZR
A16: =CONCATENATE(B16,"-",C16) -> TJ-04º Pav.-Sala Elétrica W2 | B16: TJ-04º Pav. | C16: Sala Elétrica W2 | E16: W2 | I16: https://photos.google.com/share/AF1QipOnxf0N19-SZoS0Yl0rS2KEgiBhevFZsrpr3uxkiLbBc-_-gXbdKKkerkfeefm6Ow/photo/AF1QipMMGGE-7efE0wnGXWwej2s_BXDtjVJhOShdfeKD?key=VmVLUnFTZVZGeV85R0YtUlEyQmNEXzdRamNxZWVB
A17: =CONCATENATE(B17,"-",C17) -> TJ-04º Pav.-Sala Elétrica W3 | B17: TJ-04º Pav. | C17: Sala Elétrica W3 | E17: W3 | I17: https://photos.google.com/share/AF1QipNVRUxhFeIO1SqZdW_7agi2SOUFjHN9ZGkx4_42ebwi1kW0MxB9ri-amVbSVcddRw/photo/AF1QipNRAxQQqxvbqtByq7f3pKTLyTklH9Ez5kXC6WUm?key=ZWFyWE5jREk5RmV5OUdDd2E3VWk5WkUyS1JNckxB
A18: =CONCATENATE(B18,"-",C18) -> TJ-05º Pav.- | B18: TJ-05º Pav.
A19: =CONCATENATE(B19,"-",C19) -> TJ-05º Pav.-Sala Elétrica E2 | B19: TJ-05º Pav. | C19: Sala Elétrica E2 | E19: E2
A20: =CONCATENATE(B20,"-",C20) -> TJ-05º Pav.-Sala Elétrica E3 | B20: TJ-05º Pav. | C20: Sala Elétrica E3 | E20: E3
A21: =CONCATENATE(B21,"-",C21) -> TJ-05º Pav.-Sala Elétrica W2 | B21: TJ-05º Pav. | C21: Sala Elétrica W2 | E21: W2
A22: =CONCATENATE(B22,"-",C22) -> TJ-05º Pav.-Sala Elétrica W3 | B22: TJ-05º Pav. | C22: Sala Elétrica W3 | E22: W3
A23: =CONCATENATE(B23,"-",C23) -> TJ-06º Pav.- | B23: TJ-06º Pav.
A24: =CONCATENATE(B24,"-",C24) -> TJ-06º Pav.-Sala Elétrica E2 | B24: TJ-06º Pav. | C24: Sala Elétrica E2 | E24: E2
A25: =CONCATENATE(B25,"-",C25) -> TJ-06º Pav.-Sala Elétrica E3 | B25: TJ-06º Pav. | C25: Sala Elétrica E3 | E25: E3
A26: =CONCATENATE(B26,"-",C26) -> TJ-06º Pav.-Sala Elétrica W2 | B26: TJ-06º Pav. | C26: Sala Elétrica W2 | E26: W2
A27: =CONCATENATE(B27,"-",C27) -> TJ-06º Pav.-Sala Elétrica W3 | B27: TJ-06º Pav. | C27: Sala Elétrica W3 | E27: W3
A28: =CONCATENATE(B28,"-",C28) -> TJ-07º Pav.- | B28: TJ-07º Pav.
A29: =CONCATENATE(B29,"-",C29) -> TJ-07º Pav.-Sala Elétrica E2 | B29: TJ-07º Pav. | C29: Sala Elétrica E2 | E29: E2
A30: =CONCATENATE(B30,"-",C30) -> TJ-07º Pav.-Sala Elétrica E3 | B30: TJ-07º Pav. | C30: Sala Elétrica E3 | E30: E3
A31: =CONCATENATE(B31,"-",C31) -> TJ-07º Pav.-Sala Elétrica W2 | B31: TJ-07º Pav. | C31: Sala Elétrica W2 | E31: W2
A32: =CONCATENATE(B32,"-",C32) -> TJ-07º Pav.-Sala Elétrica W3 | B32: TJ-07º Pav. | C32: Sala Elétrica W3 | E32: W3
A33: =CONCATENATE(B33,"-",C33) -> TJ-08º Pav.- | B33: TJ-08º Pav.
A34: =CONCATENATE(B34,"-",C34) -> TJ-08º Pav.-Sala Elétrica E2 | B34: TJ-08º Pav. | C34: Sala Elétrica E2 | E34: E2
A35: =CONCATENATE(B35,"-",C35) -> TJ-08º Pav.-Sala Elétrica E3 | B35: TJ-08º Pav. | C35: Sala Elétrica E3 | E35: E3
A36: =CONCATENATE(B36,"-",C36) -> TJ-08º Pav.-Sala Elétrica W2 | B36: TJ-08º Pav. | C36: Sala Elétrica W2 | E36: W2
A37: =CONCATENATE(B37,"-",C37) -> TJ-08º Pav.-Sala Elétrica W3 | B37: TJ-08º Pav. | C37: Sala Elétrica W3 | E37: W3
A38: =CONCATENATE(B38,"-",C38) -> TJ-09º Pav.- | B38: TJ-09º Pav.
A39: =CONCATENATE(B39,"-",C39) -> TJ-09º Pav.-Sala Elétrica E2 | B39: TJ-09º Pav. | C39: Sala Elétrica E2 | E39: E2
A40: =CONCATENATE(B40,"-",C40) -> TJ-09º Pav.-Sala Elétrica E3 | B40: TJ-09º Pav. | C40: Sala Elétrica E3 | E40: E3
A41: =CONCATENATE(B41,"-",C41) -> TJ-09º Pav.-Sala Elétrica W2 | B41: TJ-09º Pav. | C41: Sala Elétrica W2 | E41: W2
...

Sheet Validação
A1: SISTEMA | B1: Tipos NF | C1: Fornecedor | E1: Situação Quadro | G1: Pavimento
A2: Ar. Cond. | B2: Quadros | C2: Clavel | E2: Existente | G2: TJ-Térreo
A3: Elétrica | B3: Materiais Elétricos | C3: ABT Materiais Elétricos | E3: Novo | G3: TJ-02º Pav.
A4: Comunicação | C4: Viksul Telecom. | E4: Não Instalados | G4: TJ-03º Pav.
A5: Automação | C5: Cigame | G5: TJ-04º Pav.
C6: BM Eletro | G6: TJ-05º Pav.
C7: GMD Comercial Elétrica | G7: TJ-06º Pav.
C8: Comercial MW | G8: TJ-07º Pav.
C9: Eletro Gold | G9: TJ-08º Pav.
G10: TJ-09º Pav.
G11: TJ-10º Pav.
G12: TJ-11º Pav.
G13: TJ-12º Pav.
G14: TJ-13º Pav.
G15: TJ-14º Pav.
G16: TJ-Cobertura
G17: TJ.ANX-2º Pav.
G18: TJ.ANX-Térreo
G19: TJ.ANX-SS1
G20: TJ.ANX-SS2
G21: TJ.ANX-SS3

Sheet Diagrama

Sheet LocalBackup
A1: Localização
A2: =IFERROR(__xludf.DUMMYFUNCTION("IMPORTRANGE(""https://docs.google.com/spreadsheets/d/1PxkT-WtVeT7ZFXR4Z2e0WbSkqxChNhH4aDbJSxmkwOA/edit?usp=sharing"",""Localização!A1:j1004"")"),"NomeConc.") -> NomeConc. | B2: =IFERROR(__xludf.DUMMYFUNCTION("""COMPUTED_VALUE"""),"Pavimento") -> Pavimento | C2: =IFERROR(__xludf.DUMMYFUNCTION("""COMPUTED_VALUE"""),"2ºPav.") -> 2ºPav. | D2: =IFERROR(__xludf.DUMMYFUNCTION("""COMPUTED_VALUE"""),"Parent") -> Parent | E2: =IFERROR(__xludf.DUMMYFUNCTION("""COMPUTED_VALUE"""),"Setor") -> Setor | F2: =IFERROR(__xludf.DUMMYFUNCTION("""COMPUTED_VALUE"""),"Pin") -> Pin | G2: =IFERROR(__xludf.DUMMYFUNCTION("""COMPUTED_VALUE"""),"Link") -> Link | H2: =IFERROR(__xludf.DUMMYFUNCTION("""COMPUTED_VALUE"""),"Tipo") -> Tipo | I2: =IFERROR(__xludf.DUMMYFUNCTION("""COMPUTED_VALUE"""),"Foto360º") -> Foto360º | J2: =IFERROR(__xludf.DUMMYFUNCTION("""COMPUTED_VALUE"""),"Porta") -> Porta
A3: =IFERROR(__xludf.DUMMYFUNCTION("""COMPUTED_VALUE"""),"2ºPav.") -> 2ºPav. | B3: =IFERROR(__xludf.DUMMYFUNCTION("""COMPUTED_VALUE"""),"2ºPav.") -> 2ºPav. | C3: =IFERROR(__xludf.DUMMYFUNCTION("""COMPUTED_VALUE"""),"2ºPav.") -> 2ºPav. | E3: =IFERROR(__xludf.DUMMYFUNCTION("""COMPUTED_VALUE"""),"A") -> A | F3: =IFERROR(__xludf.DUMMYFUNCTION("""COMPUTED_VALUE"""),1.0) -> 1 | G3: =IFERROR(__xludf.DUMMYFUNCTION("""COMPUTED_VALUE"""),"https://myhub.autodesk360.com/ue29d95bb/g/projects/20210514412106331/data/dXJuOmFkc2sud2lwcHJvZDpmcy5mb2xkZXI6Y28ucU04eGNtQzdReXliS0NURmJQYUFTQQ/dXJuOmFkc2sud2lwcHJvZDpkbS5saW5lYWdlOlh4SzhZNFhHVEN5WDNPT29yLUd3WlE/viewer?version=1&commentId=urn:adsk.commen"&"ts:social.comment:655ec21f86d64b45b2f2d31b25a4e13b&showComments=1&guid=6882be48-6626-5238-d3df-94e9f0a0019d") -> https://myhub.autodesk360.com/ue29d95bb/g/projects/20210514412106331/data/dXJuOmFkc2sud2lwcHJvZDpmcy5mb2xkZXI6Y28ucU04eGNtQzdReXliS0NURmJQYUFTQQ/dXJuOmFkc2sud2lwcHJvZDpkbS5saW5lYWdlOlh4SzhZNFhHVEN5WDNPT29yLUd3WlE/viewer?version=1&commentId=urn:adsk.comments:social.comment:655ec21f86d64b45b2f2d31b25a4e13b&showComments=1&guid=6882be48-6626-5238-d3df-94e9f0a0019d | H3: =IFERROR(__xludf.DUMMYFUNCTION("""COMPUTED_VALUE"""),"Geral") -> Geral | I3: =IFERROR(__xludf.DUMMYFUNCTION("""COMPUTED_VALUE"""),"https://photos.google.com/share/AF1QipMp8IwP1oaaM3uZxlFtOvkb9lpx3bxXWYKmZy5pRl7ZdMCEu7RH7rnzo4fFMbH0NA?key=a1ZQWFp2S2R2Vkp1cVRuX3dGTVVXRVJRQm9udUFB") -> https://photos.google.com/share/AF1QipMp8IwP1oaaM3uZxlFtOvkb9lpx3bxXWYKmZy5pRl7ZdMCEu7RH7rnzo4fFMbH0NA?key=a1ZQWFp2S2R2Vkp1cVRuX3dGTVVXRVJRQm9udUFB
A4: =IFERROR(__xludf.DUMMYFUNCTION("""COMPUTED_VALUE"""),"2ºPav.-Administrativa FME") -> 2ºPav.-Administrativa FME | B4: =IFERROR(__xludf.DUMMYFUNCTION("""COMPUTED_VALUE"""),"2ºPav.") -> 2ºPav. | C4: =IFERROR(__xludf.DUMMYFUNCTION("""COMPUTED_VALUE"""),"Administrativa FME") -> Administrativa FME | D4: =IFERROR(__xludf.DUMMYFUNCTION("""COMPUTED_VALUE"""),"2ºPav.") -> 2ºPav. | E4: =IFERROR(__xludf.DUMMYFUNCTION("""COMPUTED_VALUE"""),"A") -> A | G4: =IFERROR(__xludf.DUMMYFUNCTION("""COMPUTED_VALUE"""),"https://myhub.autodesk360.com/ue29d95bb/g/projects/20210514412106331/data/dXJuOmFkc2sud2lwcHJvZDpmcy5mb2xkZXI6Y28ucU04eGNtQzdReXliS0NURmJQYUFTQQ/dXJuOmFkc2sud2lwcHJvZDpkbS5saW5lYWdlOlh4SzhZNFhHVEN5WDNPT29yLUd3WlE/viewer?version=1&commentId=urn:adsk.commen"&"ts:social.comment:3c6e25073639441e8e347606248889a2&showComments=1&guid=6882be48-6626-5238-d3df-94e9f0a0019d") -> https://myhub.autodesk360.com/ue29d95bb/g/projects/20210514412106331/data/dXJuOmFkc2sud2lwcHJvZDpmcy5mb2xkZXI6Y28ucU04eGNtQzdReXliS0NURmJQYUFTQQ/dXJuOmFkc2sud2lwcHJvZDpkbS5saW5lYWdlOlh4SzhZNFhHVEN5WDNPT29yLUd3WlE/viewer?version=1&commentId=urn:adsk.comments:social.comment:3c6e25073639441e8e347606248889a2&showComments=1&guid=6882be48-6626-5238-d3df-94e9f0a0019d | H4: =IFERROR(__xludf.DUMMYFUNCTION("""COMPUTED_VALUE"""),"Outros") -> Outros
A5: =IFERROR(__xludf.DUMMYFUNCTION("""COMPUTED_VALUE"""),"2ºPav.-Antecâmara Setor A") -> 2ºPav.-Antecâmara Setor A | B5: =IFERROR(__xludf.DUMMYFUNCTION("""COMPUTED_VALUE"""),"2ºPav.") -> 2ºPav. | C5: =IFERROR(__xludf.DUMMYFUNCTION("""COMPUTED_VALUE"""),"Antecâmara Setor A") -> Antecâmara Setor A | D5: =IFERROR(__xludf.DUMMYFUNCTION("""COMPUTED_VALUE"""),"2ºPav.") -> 2ºPav. | E5: =IFERROR(__xludf.DUMMYFUNCTION("""COMPUTED_VALUE"""),"A") -> A | F5: =IFERROR(__xludf.DUMMYFUNCTION("""COMPUTED_VALUE"""),61.0) -> 61 | G5: =IFERROR(__xludf.DUMMYFUNCTION("""COMPUTED_VALUE"""),"https://myhub.autodesk360.com/ue29d95bb/g/projects/20210514412106331/data/dXJuOmFkc2sud2lwcHJvZDpmcy5mb2xkZXI6Y28ucU04eGNtQzdReXliS0NURmJQYUFTQQ/dXJuOmFkc2sud2lwcHJvZDpkbS5saW5lYWdlOlh4SzhZNFhHVEN5WDNPT29yLUd3WlE/viewer?version=1&commentId=urn:adsk.commen"&"ts:social.comment:7b8291e7388243c5a7a1d954f8752a0e&showComments=1&guid=6882be48-6626-5238-d3df-94e9f0a0019d") -> https://myhub.autodesk360.com/ue29d95bb/g/projects/20210514412106331/data/dXJuOmFkc2sud2lwcHJvZDpmcy5mb2xkZXI6Y28ucU04eGNtQzdReXliS0NURmJQYUFTQQ/dXJuOmFkc2sud2lwcHJvZDpkbS5saW5lYWdlOlh4SzhZNFhHVEN5WDNPT29yLUd3WlE/viewer?version=1&commentId=urn:adsk.comments:social.comment:7b8291e7388243c5a7a1d954f8752a0e&showComments=1&guid=6882be48-6626-5238-d3df-94e9f0a0019d | H5: =IFERROR(__xludf.DUMMYFUNCTION("""COMPUTED_VALUE"""),"Circulação / Corredores") -> Circulação / Corredores
A6: =IFERROR(__xludf.DUMMYFUNCTION("""COMPUTED_VALUE"""),"2ºPav.-Antecâmara Setor B") -> 2ºPav.-Antecâmara Setor B | B6: =IFERROR(__xludf.DUMMYFUNCTION("""COMPUTED_VALUE"""),"2ºPav.") -> 2ºPav. | C6: =IFERROR(__xludf.DUMMYFUNCTION("""COMPUTED_VALUE"""),"Antecâmara Setor B") -> Antecâmara Setor B | D6: =IFERROR(__xludf.DUMMYFUNCTION("""COMPUTED_VALUE"""),"2ºPav.") -> 2ºPav. | E6: =IFERROR(__xludf.DUMMYFUNCTION("""COMPUTED_VALUE"""),"B") -> B | F6: =IFERROR(__xludf.DUMMYFUNCTION("""COMPUTED_VALUE"""),59.0) -> 59 | G6: =IFERROR(__xludf.DUMMYFUNCTION("""COMPUTED_VALUE"""),"https://myhub.autodesk360.com/ue29d95bb/g/projects/20210514412106331/data/dXJuOmFkc2sud2lwcHJvZDpmcy5mb2xkZXI6Y28ucU04eGNtQzdReXliS0NURmJQYUFTQQ/dXJuOmFkc2sud2lwcHJvZDpkbS5saW5lYWdlOlh4SzhZNFhHVEN5WDNPT29yLUd3WlE/viewer?version=1&commentId=urn:adsk.commen"&"ts:social.comment:436cc99776e744639bf94d5149a12056&showComments=1&guid=6882be48-6626-5238-d3df-94e9f0a0019d") -> https://myhub.autodesk360.com/ue29d95bb/g/projects/20210514412106331/data/dXJuOmFkc2sud2lwcHJvZDpmcy5mb2xkZXI6Y28ucU04eGNtQzdReXliS0NURmJQYUFTQQ/dXJuOmFkc2sud2lwcHJvZDpkbS5saW5lYWdlOlh4SzhZNFhHVEN5WDNPT29yLUd3WlE/viewer?version=1&commentId=urn:adsk.comments:social.comment:436cc99776e744639bf94d5149a12056&showComments=1&guid=6882be48-6626-5238-d3df-94e9f0a0019d | H6: =IFERROR(__xludf.DUMMYFUNCTION("""COMPUTED_VALUE"""),"Circulação / Corredores") -> Circulação / Corredores | I6: =IFERROR(__xludf.DUMMYFUNCTION("""COMPUTED_VALUE"""),"https://photos.google.com/search/2%C2%BAPav.-Antec%C3%A2mara%20Setor%20B") -> https://photos.google.com/search/2%C2%BAPav.-Antec%C3%A2mara%20Setor%20B
A7: =IFERROR(__xludf.DUMMYFUNCTION("""COMPUTED_VALUE"""),"2ºPav.-Área Registro de Pacientes") -> 2ºPav.-Área Registro de Pacientes | B7: =IFERROR(__xludf.DUMMYFUNCTION("""COMPUTED_VALUE"""),"2ºPav.") -> 2ºPav. | C7: =IFERROR(__xludf.DUMMYFUNCTION("""COMPUTED_VALUE"""),"Área Registro de Pacientes") -> Área Registro de Pacientes | D7: =IFERROR(__xludf.DUMMYFUNCTION("""COMPUTED_VALUE"""),"2ºPav.") -> 2ºPav. | E7: =IFERROR(__xludf.DUMMYFUNCTION("""COMPUTED_VALUE"""),"A") -> A | G7: =IFERROR(__xludf.DUMMYFUNCTION("""COMPUTED_VALUE"""),"https://myhub.autodesk360.com/ue29d95bb/g/projects/20210514412106331/data/dXJuOmFkc2sud2lwcHJvZDpmcy5mb2xkZXI6Y28ucU04eGNtQzdReXliS0NURmJQYUFTQQ/dXJuOmFkc2sud2lwcHJvZDpkbS5saW5lYWdlOlh4SzhZNFhHVEN5WDNPT29yLUd3WlE/viewer?version=1&commentId=urn:adsk.commen"&"ts:social.comment:c54e018dfcd6449cb526a56a57d62ee8&showComments=1&guid=6882be48-6626-5238-d3df-94e9f0a0019d") -> https://myhub.autodesk360.com/ue29d95bb/g/projects/20210514412106331/data/dXJuOmFkc2sud2lwcHJvZDpmcy5mb2xkZXI6Y28ucU04eGNtQzdReXliS0NURmJQYUFTQQ/dXJuOmFkc2sud2lwcHJvZDpkbS5saW5lYWdlOlh4SzhZNFhHVEN5WDNPT29yLUd3WlE/viewer?version=1&commentId=urn:adsk.comments:social.comment:c54e018dfcd6449cb526a56a57d62ee8&showComments=1&guid=6882be48-6626-5238-d3df-94e9f0a0019d | H7: =IFERROR(__xludf.DUMMYFUNCTION("""COMPUTED_VALUE"""),"Recepção") -> Recepção | I7: =IFERROR(__xludf.DUMMYFUNCTION("""COMPUTED_VALUE"""),"https://photos.google.com/search/2%C2%BAPav.-%C3%81rea%20Registro%20de%20Pacientes") -> https://photos.google.com/search/2%C2%BAPav.-%C3%81rea%20Registro%20de%20Pacientes
A8: =IFERROR(__xludf.DUMMYFUNCTION("""COMPUTED_VALUE"""),"2ºPav.-Armazenamento FME") -> 2ºPav.-Armazenamento FME | B8: =IFERROR(__xludf.DUMMYFUNCTION("""COMPUTED_VALUE"""),"2ºPav.") -> 2ºPav. | C8: =IFERROR(__xludf.DUMMYFUNCTION("""COMPUTED_VALUE"""),"Armazenamento FME") -> Armazenamento FME | D8: =IFERROR(__xludf.DUMMYFUNCTION("""COMPUTED_VALUE"""),"2ºPav.") -> 2ºPav. | E8: =IFERROR(__xludf.DUMMYFUNCTION("""COMPUTED_VALUE"""),"A") -> A | G8: =IFERROR(__xludf.DUMMYFUNCTION("""COMPUTED_VALUE"""),"https://myhub.autodesk360.com/ue29d95bb/g/projects/20210514412106331/data/dXJuOmFkc2sud2lwcHJvZDpmcy5mb2xkZXI6Y28ucU04eGNtQzdReXliS0NURmJQYUFTQQ/dXJuOmFkc2sud2lwcHJvZDpkbS5saW5lYWdlOlh4SzhZNFhHVEN5WDNPT29yLUd3WlE/viewer?version=1&commentId=urn:adsk.commen"&"ts:social.comment:2092d960dc73478c937a3506afaa9454&showComments=1&guid=6882be48-6626-5238-d3df-94e9f0a0019d") -> https://myhub.autodesk360.com/ue29d95bb/g/projects/20210514412106331/data/dXJuOmFkc2sud2lwcHJvZDpmcy5mb2xkZXI6Y28ucU04eGNtQzdReXliS0NURmJQYUFTQQ/dXJuOmFkc2sud2lwcHJvZDpkbS5saW5lYWdlOlh4SzhZNFhHVEN5WDNPT29yLUd3WlE/viewer?version=1&commentId=urn:adsk.comments:social.comment:2092d960dc73478c937a3506afaa9454&showComments=1&guid=6882be48-6626-5238-d3df-94e9f0a0019d | H8: =IFERROR(__xludf.DUMMYFUNCTION("""COMPUTED_VALUE"""),"Outros") -> Outros | I8: =IFERROR(__xludf.DUMMYFUNCTION("""COMPUTED_VALUE"""),"https://photos.google.com/search/2%C2%BAPav.-Armazenamento%20FME") -> https://photos.google.com/search/2%C2%BAPav.-Armazenamento%20FME
A9: =IFERROR(__xludf.DUMMYFUNCTION("""COMPUTED_VALUE"""),"2ºPav.-Assistente Social") -> 2ºPav.-Assistente Social | B9: =IFERROR(__xludf.DUMMYFUNCTION("""COMPUTED_VALUE"""),"2ºPav.") -> 2ºPav. | C9: =IFERROR(__xludf.DUMMYFUNCTION("""COMPUTED_VALUE"""),"Assistente Social") -> Assistente Social | D9: =IFERROR(__xludf.DUMMYFUNCTION("""COMPUTED_VALUE"""),"2ºPav.") -> 2ºPav. | E9: =IFERROR(__xludf.DUMMYFUNCTION("""COMPUTED_VALUE"""),"A") -> A | G9: =IFERROR(__xludf.DUMMYFUNCTION("""COMPUTED_VALUE"""),"https://myhub.autodesk360.com/ue29d95bb/g/projects/20210514412106331/data/dXJuOmFkc2sud2lwcHJvZDpmcy5mb2xkZXI6Y28ucU04eGNtQzdReXliS0NURmJQYUFTQQ/dXJuOmFkc2sud2lwcHJvZDpkbS5saW5lYWdlOlh4SzhZNFhHVEN5WDNPT29yLUd3WlE/viewer?version=1&commentId=urn:adsk.commen"&"ts:social.comment:b308e19492464a80b8d6ea28bd847077&showComments=1&guid=6882be48-6626-5238-d3df-94e9f0a0019d") -> https://myhub.autodesk360.com/ue29d95bb/g/projects/20210514412106331/data/dXJuOmFkc2sud2lwcHJvZDpmcy5mb2xkZXI6Y28ucU04eGNtQzdReXliS0NURmJQYUFTQQ/dXJuOmFkc2sud2lwcHJvZDpkbS5saW5lYWdlOlh4SzhZNFhHVEN5WDNPT29yLUd3WlE/viewer?version=1&commentId=urn:adsk.comments:social.comment:b308e19492464a80b8d6ea28bd847077&showComments=1&guid=6882be48-6626-5238-d3df-94e9f0a0019d | H9: =IFERROR(__xludf.DUMMYFUNCTION("""COMPUTED_VALUE"""),"Consultório") -> Consultório | I9: =IFERROR(__xludf.DUMMYFUNCTION("""COMPUTED_VALUE"""),"https://photos.google.com/search/2%C2%BAPav.-Assistente%20Social") -> https://photos.google.com/search/2%C2%BAPav.-Assistente%20Social
A10: =IFERROR(__xludf.DUMMYFUNCTION("""COMPUTED_VALUE"""),"2ºPav.-Box Privativo Aplicação Quimioterápicos") -> 2ºPav.-Box Privativo Aplicação Quimioterápicos | B10: =IFERROR(__xludf.DUMMYFUNCTION("""COMPUTED_VALUE"""),"2ºPav.") -> 2ºPav. | C10: =IFERROR(__xludf.DUMMYFUNCTION("""COMPUTED_VALUE"""),"Box Privativo Aplicação Quimioterápicos") -> Box Privativo Aplicação Quimioterápicos | D10: =IFERROR(__xludf.DUMMYFUNCTION("""COMPUTED_VALUE"""),"2ºPav.") -> 2ºPav. | E10: =IFERROR(__xludf.DUMMYFUNCTION("""COMPUTED_VALUE"""),"A") -> A | G10: =IFERROR(__xludf.DUMMYFUNCTION("""COMPUTED_VALUE"""),"https://myhub.autodesk360.com/ue29d95bb/g/projects/20210514412106331/data/dXJuOmFkc2sud2lwcHJvZDpmcy5mb2xkZXI6Y28ucU04eGNtQzdReXliS0NURmJQYUFTQQ/dXJuOmFkc2sud2lwcHJvZDpkbS5saW5lYWdlOlh4SzhZNFhHVEN5WDNPT29yLUd3WlE/viewer?version=1&commentId=urn:adsk.commen"&"ts:social.comment:bce2bf4a74b24481bc21c127432efe65&showComments=1&guid=6882be48-6626-5238-d3df-94e9f0a0019d") -> https://myhub.autodesk360.com/ue29d95bb/g/projects/20210514412106331/data/dXJuOmFkc2sud2lwcHJvZDpmcy5mb2xkZXI6Y28ucU04eGNtQzdReXliS0NURmJQYUFTQQ/dXJuOmFkc2sud2lwcHJvZDpkbS5saW5lYWdlOlh4SzhZNFhHVEN5WDNPT29yLUd3WlE/viewer?version=1&commentId=urn:adsk.comments:social.comment:bce2bf4a74b24481bc21c127432efe65&showComments=1&guid=6882be48-6626-5238-d3df-94e9f0a0019d | H10: =IFERROR(__xludf.DUMMYFUNCTION("""COMPUTED_VALUE"""),"Aplicação") -> Aplicação
A11: =IFERROR(__xludf.DUMMYFUNCTION("""COMPUTED_VALUE"""),"2ºPav.-Circulação Monta Carga") -> 2ºPav.-Circulação Monta Carga | B11: =IFERROR(__xludf.DUMMYFUNCTION("""COMPUTED_VALUE"""),"2ºPav.") -> 2ºPav. | C11: =IFERROR(__xludf.DUMMYFUNCTION("""COMPUTED_VALUE"""),"Circulação Monta Carga") -> Circulação Monta Carga | D11: =IFERROR(__xludf.DUMMYFUNCTION("""COMPUTED_VALUE"""),"2ºPav.") -> 2ºPav. | E11: =IFERROR(__xludf.DUMMYFUNCTION("""COMPUTED_VALUE"""),"A") -> A | F11: =IFERROR(__xludf.DUMMYFUNCTION("""COMPUTED_VALUE"""),12.0) -> 12 | G11: =IFERROR(__xludf.DUMMYFUNCTION("""COMPUTED_VALUE"""),"https://myhub.autodesk360.com/ue29d95bb/g/projects/20210514412106331/data/dXJuOmFkc2sud2lwcHJvZDpmcy5mb2xkZXI6Y28ucU04eGNtQzdReXliS0NURmJQYUFTQQ/dXJuOmFkc2sud2lwcHJvZDpkbS5saW5lYWdlOlh4SzhZNFhHVEN5WDNPT29yLUd3WlE/viewer?version=1&commentId=urn:adsk.commen"&"ts:social.comment:b4e772a941f64d0a803b93128435622c&showComments=1&guid=6882be48-6626-5238-d3df-94e9f0a0019d") -> https://myhub.autodesk360.com/ue29d95bb/g/projects/20210514412106331/data/dXJuOmFkc2sud2lwcHJvZDpmcy5mb2xkZXI6Y28ucU04eGNtQzdReXliS0NURmJQYUFTQQ/dXJuOmFkc2sud2lwcHJvZDpkbS5saW5lYWdlOlh4SzhZNFhHVEN5WDNPT29yLUd3WlE/viewer?version=1&commentId=urn:adsk.comments:social.comment:b4e772a941f64d0a803b93128435622c&showComments=1&guid=6882be48-6626-5238-d3df-94e9f0a0019d | H11: =IFERROR(__xludf.DUMMYFUNCTION("""COMPUTED_VALUE"""),"Outros") -> Outros | I11: =IFERROR(__xludf.DUMMYFUNCTION("""COMPUTED_VALUE"""),"https://photos.google.com/search/2%C2%BAPav.-Circula%C3%A7%C3%A3o%20Monta%20Carga") -> https://photos.google.com/search/2%C2%BAPav.-Circula%C3%A7%C3%A3o%20Monta%20Carga
A12: =IFERROR(__xludf.DUMMYFUNCTION("""COMPUTED_VALUE"""),"2ºPav.-Consultório") -> 2ºPav.-Consultório | B12: =IFERROR(__xludf.DUMMYFUNCTION("""COMPUTED_VALUE"""),"2ºPav.") -> 2ºPav. | C12: =IFERROR(__xludf.DUMMYFUNCTION("""COMPUTED_VALUE"""),"Consultório") -> Consultório | D12: =IFERROR(__xludf.DUMMYFUNCTION("""COMPUTED_VALUE"""),"2ºPav.") -> 2ºPav. | E12: =IFERROR(__xludf.DUMMYFUNCTION("""COMPUTED_VALUE"""),"B") -> B | G12: =IFERROR(__xludf.DUMMYFUNCTION("""COMPUTED_VALUE"""),"https://myhub.autodesk360.com/ue29d95bb/g/projects/20210514412106331/data/dXJuOmFkc2sud2lwcHJvZDpmcy5mb2xkZXI6Y28ucU04eGNtQzdReXliS0NURmJQYUFTQQ/dXJuOmFkc2sud2lwcHJvZDpkbS5saW5lYWdlOlh4SzhZNFhHVEN5WDNPT29yLUd3WlE/viewer?version=1&commentId=urn:adsk.commen"&"ts:social.comment:d28eb067f9f24da08280197c8ac30ff6&showComments=1&guid=6882be48-6626-5238-d3df-94e9f0a0019d") -> https://myhub.autodesk360.com/ue29d95bb/g/projects/20210514412106331/data/dXJuOmFkc2sud2lwcHJvZDpmcy5mb2xkZXI6Y28ucU04eGNtQzdReXliS0NURmJQYUFTQQ/dXJuOmFkc2sud2lwcHJvZDpkbS5saW5lYWdlOlh4SzhZNFhHVEN5WDNPT29yLUd3WlE/viewer?version=1&commentId=urn:adsk.comments:social.comment:d28eb067f9f24da08280197c8ac30ff6&showComments=1&guid=6882be48-6626-5238-d3df-94e9f0a0019d | H12: =IFERROR(__xludf.DUMMYFUNCTION("""COMPUTED_VALUE"""),"Consultório") -> Consultório
A13: =IFERROR(__xludf.DUMMYFUNCTION("""COMPUTED_VALUE"""),"2ºPav.-Consultório FME") -> 2ºPav.-Consultório FME | B13: =IFERROR(__xludf.DUMMYFUNCTION("""COMPUTED_VALUE"""),"2ºPav.") -> 2ºPav. | C13: =IFERROR(__xludf.DUMMYFUNCTION("""COMPUTED_VALUE"""),"Consultório FME") -> Consultório FME | D13: =IFERROR(__xludf.DUMMYFUNCTION("""COMPUTED_VALUE"""),"2ºPav.") -> 2ºPav. | E13: =IFERROR(__xludf.DUMMYFUNCTION("""COMPUTED_VALUE"""),"A") -> A | G13: =IFERROR(__xludf.DUMMYFUNCTION("""COMPUTED_VALUE"""),"https://myhub.autodesk360.com/ue29d95bb/g/projects/20210514412106331/data/dXJuOmFkc2sud2lwcHJvZDpmcy5mb2xkZXI6Y28ucU04eGNtQzdReXliS0NURmJQYUFTQQ/dXJuOmFkc2sud2lwcHJvZDpkbS5saW5lYWdlOlh4SzhZNFhHVEN5WDNPT29yLUd3WlE/viewer?version=1&commentId=urn:adsk.commen"&"ts:social.comment:54997e72ff6b450fa1b7246214f14ddf&showComments=1&guid=6882be48-6626-5238-d3df-94e9f0a0019d") -> https://myhub.autodesk360.com/ue29d95bb/g/projects/20210514412106331/data/dXJuOmFkc2sud2lwcHJvZDpmcy5mb2xkZXI6Y28ucU04eGNtQzdReXliS0NURmJQYUFTQQ/dXJuOmFkc2sud2lwcHJvZDpkbS5saW5lYWdlOlh4SzhZNFhHVEN5WDNPT29yLUd3WlE/viewer?version=1&commentId=urn:adsk.comments:social.comment:54997e72ff6b450fa1b7246214f14ddf&showComments=1&guid=6882be48-6626-5238-d3df-94e9f0a0019d | H13: =IFERROR(__xludf.DUMMYFUNCTION("""COMPUTED_VALUE"""),"Consultório") -> Consultório
A14: =IFERROR(__xludf.DUMMYFUNCTION("""COMPUTED_VALUE"""),"2ºPav.-Consultório Psicologia") -> 2ºPav.-Consultório Psicologia | B14: =IFERROR(__xludf.DUMMYFUNCTION("""COMPUTED_VALUE"""),"2ºPav.") -> 2ºPav. | C14: =IFERROR(__xludf.DUMMYFUNCTION("""COMPUTED_VALUE"""),"Consultório Psicologia") -> Consultório Psicologia | D14: =IFERROR(__xludf.DUMMYFUNCTION("""COMPUTED_VALUE"""),"2ºPav.") -> 2ºPav. | E14: =IFERROR(__xludf.DUMMYFUNCTION("""COMPUTED_VALUE"""),"A") -> A | G14: =IFERROR(__xludf.DUMMYFUNCTION("""COMPUTED_VALUE"""),"https://myhub.autodesk360.com/ue29d95bb/g/projects/20210514412106331/data/dXJuOmFkc2sud2lwcHJvZDpmcy5mb2xkZXI6Y28ucU04eGNtQzdReXliS0NURmJQYUFTQQ/dXJuOmFkc2sud2lwcHJvZDpkbS5saW5lYWdlOlh4SzhZNFhHVEN5WDNPT29yLUd3WlE/viewer?version=1&commentId=urn:adsk.commen"&"ts:social.comment:3892f26f5af946c1b01851f8081432ae&showComments=1&guid=6882be48-6626-5238-d3df-94e9f0a0019d") -> https://myhub.autodesk360.com/ue29d95bb/g/projects/20210514412106331/data/dXJuOmFkc2sud2lwcHJvZDpmcy5mb2xkZXI6Y28ucU04eGNtQzdReXliS0NURmJQYUFTQQ/dXJuOmFkc2sud2lwcHJvZDpkbS5saW5lYWdlOlh4SzhZNFhHVEN5WDNPT29yLUd3WlE/viewer?version=1&commentId=urn:adsk.comments:social.comment:3892f26f5af946c1b01851f8081432ae&showComments=1&guid=6882be48-6626-5238-d3df-94e9f0a0019d | H14: =IFERROR(__xludf.DUMMYFUNCTION("""COMPUTED_VALUE"""),"Consultório") -> Consultório
A15: =IFERROR(__xludf.DUMMYFUNCTION("""COMPUTED_VALUE"""),"2ºPav.-Copa") -> 2ºPav.-Copa | B15: =IFERROR(__xludf.DUMMYFUNCTION("""COMPUTED_VALUE"""),"2ºPav.") -> 2ºPav. | C15: =IFERROR(__xludf.DUMMYFUNCTION("""COMPUTED_VALUE"""),"Copa") -> Copa | D15: =IFERROR(__xludf.DUMMYFUNCTION("""COMPUTED_VALUE"""),"2ºPav.") -> 2ºPav. | E15: =IFERROR(__xludf.DUMMYFUNCTION("""COMPUTED_VALUE"""),"B") -> B | G15: =IFERROR(__xludf.DUMMYFUNCTION("""COMPUTED_VALUE"""),"https://myhub.autodesk360.com/ue29d95bb/g/projects/20210514412106331/data/dXJuOmFkc2sud2lwcHJvZDpmcy5mb2xkZXI6Y28ucU04eGNtQzdReXliS0NURmJQYUFTQQ/dXJuOmFkc2sud2lwcHJvZDpkbS5saW5lYWdlOlh4SzhZNFhHVEN5WDNPT29yLUd3WlE/viewer?version=1&commentId=urn:adsk.commen"&"ts:social.comment:c4957477c6284c6bae3310116d667428&showComments=1&guid=6882be48-6626-5238-d3df-94e9f0a0019d") -> https://myhub.autodesk360.com/ue29d95bb/g/projects/20210514412106331/data/dXJuOmFkc2sud2lwcHJvZDpmcy5mb2xkZXI6Y28ucU04eGNtQzdReXliS0NURmJQYUFTQQ/dXJuOmFkc2sud2lwcHJvZDpkbS5saW5lYWdlOlh4SzhZNFhHVEN5WDNPT29yLUd3WlE/viewer?version=1&commentId=urn:adsk.comments:social.comment:c4957477c6284c6bae3310116d667428&showComments=1&guid=6882be48-6626-5238-d3df-94e9f0a0019d | H15: =IFERROR(__xludf.DUMMYFUNCTION("""COMPUTED_VALUE"""),"Copa") -> Copa
A16: =IFERROR(__xludf.DUMMYFUNCTION("""COMPUTED_VALUE"""),"2ºPav.-Copa Funcionários") -> 2ºPav.-Copa Funcionários | B16: =IFERROR(__xludf.DUMMYFUNCTION("""COMPUTED_VALUE"""),"2ºPav.") -> 2ºPav. | C16: =IFERROR(__xludf.DUMMYFUNCTION("""COMPUTED_VALUE"""),"Copa Funcionários") -> Copa Funcionários | D16: =IFERROR(__xludf.DUMMYFUNCTION("""COMPUTED_VALUE"""),"2ºPav.") -> 2ºPav. | E16: =IFERROR(__xludf.DUMMYFUNCTION("""COMPUTED_VALUE"""),"A") -> A | G16: =IFERROR(__xludf.DUMMYFUNCTION("""COMPUTED_VALUE"""),"https://myhub.autodesk360.com/ue29d95bb/g/projects/20210514412106331/data/dXJuOmFkc2sud2lwcHJvZDpmcy5mb2xkZXI6Y28ucU04eGNtQzdReXliS0NURmJQYUFTQQ/dXJuOmFkc2sud2lwcHJvZDpkbS5saW5lYWdlOlh4SzhZNFhHVEN5WDNPT29yLUd3WlE/viewer?version=1&commentId=urn:adsk.commen"&"ts:social.comment:e13102bdbe6d42b78d5880435c850464&showComments=1&guid=6882be48-6626-5238-d3df-94e9f0a0019d") -> https://myhub.autodesk360.com/ue29d95bb/g/projects/20210514412106331/data/dXJuOmFkc2sud2lwcHJvZDpmcy5mb2xkZXI6Y28ucU04eGNtQzdReXliS0NURmJQYUFTQQ/dXJuOmFkc2sud2lwcHJvZDpkbS5saW5lYWdlOlh4SzhZNFhHVEN5WDNPT29yLUd3WlE/viewer?version=1&commentId=urn:adsk.comments:social.comment:e13102bdbe6d42b78d5880435c850464&showComments=1&guid=6882be48-6626-5238-d3df-94e9f0a0019d | H16: =IFERROR(__xludf.DUMMYFUNCTION("""COMPUTED_VALUE"""),"Copa") -> Copa
A17: =IFERROR(__xludf.DUMMYFUNCTION("""COMPUTED_VALUE"""),"2ºPav.-Corredor Central Setor A") -> 2ºPav.-Corredor Central Setor A | B17: =IFERROR(__xludf.DUMMYFUNCTION("""COMPUTED_VALUE"""),"2ºPav.") -> 2ºPav. | C17: =IFERROR(__xludf.DUMMYFUNCTION("""COMPUTED_VALUE"""),"Corredor Central Setor A") -> Corredor Central Setor A | D17: =IFERROR(__xludf.DUMMYFUNCTION("""COMPUTED_VALUE"""),"2ºPav.") -> 2ºPav. | E17: =IFERROR(__xludf.DUMMYFUNCTION("""COMPUTED_VALUE"""),"A") -> A | F17: =IFERROR(__xludf.DUMMYFUNCTION("""COMPUTED_VALUE"""),63.0) -> 63 | G17: =IFERROR(__xludf.DUMMYFUNCTION("""COMPUTED_VALUE"""),"https://myhub.autodesk360.com/ue29d95bb/g/projects/20210514412106331/data/dXJuOmFkc2sud2lwcHJvZDpmcy5mb2xkZXI6Y28ucU04eGNtQzdReXliS0NURmJQYUFTQQ/dXJuOmFkc2sud2lwcHJvZDpkbS5saW5lYWdlOlh4SzhZNFhHVEN5WDNPT29yLUd3WlE/viewer?version=1&commentId=urn:adsk.commen"&"ts:social.comment:05a9839aff294e7d9284043d76be4cba&showComments=1&guid=6882be48-6626-5238-d3df-94e9f0a0019d") -> https://myhub.autodesk360.com/ue29d95bb/g/projects/20210514412106331/data/dXJuOmFkc2sud2lwcHJvZDpmcy5mb2xkZXI6Y28ucU04eGNtQzdReXliS0NURmJQYUFTQQ/dXJuOmFkc2sud2lwcHJvZDpkbS5saW5lYWdlOlh4SzhZNFhHVEN5WDNPT29yLUd3WlE/viewer?version=1&commentId=urn:adsk.comments:social.comment:05a9839aff294e7d9284043d76be4cba&showComments=1&guid=6882be48-6626-5238-d3df-94e9f0a0019d | H17: =IFERROR(__xludf.DUMMYFUNCTION("""COMPUTED_VALUE"""),"Circulação / Corredores") -> Circulação / Corredores | I17: =IFERROR(__xludf.DUMMYFUNCTION("""COMPUTED_VALUE"""),"https://photos.google.com/search/2%C2%BAPav.-Corredor%20Central%20Setor%20A") -> https://photos.google.com/search/2%C2%BAPav.-Corredor%20Central%20Setor%20A
A18: =IFERROR(__xludf.DUMMYFUNCTION("""COMPUTED_VALUE"""),"2ºPav.-Corredor Central Setor B") -> 2ºPav.-Corredor Central Setor B | B18: =IFERROR(__xludf.DUMMYFUNCTION("""COMPUTED_VALUE"""),"2ºPav.") -> 2ºPav. | C18: =IFERROR(__xludf.DUMMYFUNCTION("""COMPUTED_VALUE"""),"Corredor Central Setor B") -> Corredor Central Setor B | D18: =IFERROR(__xludf.DUMMYFUNCTION("""COMPUTED_VALUE"""),"2ºPav.") -> 2ºPav. | E18: =IFERROR(__xludf.DUMMYFUNCTION("""COMPUTED_VALUE"""),"B") -> B | F18: =IFERROR(__xludf.DUMMYFUNCTION("""COMPUTED_VALUE"""),64.0) -> 64 | G18: =IFERROR(__xludf.DUMMYFUNCTION("""COMPUTED_VALUE"""),"https://myhub.autodesk360.com/ue29d95bb/g/projects/20210514412106331/data/dXJuOmFkc2sud2lwcHJvZDpmcy5mb2xkZXI6Y28ucU04eGNtQzdReXliS0NURmJQYUFTQQ/dXJuOmFkc2sud2lwcHJvZDpkbS5saW5lYWdlOlh4SzhZNFhHVEN5WDNPT29yLUd3WlE/viewer?version=1&commentId=urn:adsk.commen"&"ts:social.comment:1882645c37d747daaaa888df63f31ddd&showComments=1&guid=6882be48-6626-5238-d3df-94e9f0a0019d") -> https://myhub.autodesk360.com/ue29d95bb/g/projects/20210514412106331/data/dXJuOmFkc2sud2lwcHJvZDpmcy5mb2xkZXI6Y28ucU04eGNtQzdReXliS0NURmJQYUFTQQ/dXJuOmFkc2sud2lwcHJvZDpkbS5saW5lYWdlOlh4SzhZNFhHVEN5WDNPT29yLUd3WlE/viewer?version=1&commentId=urn:adsk.comments:social.comment:1882645c37d747daaaa888df63f31ddd&showComments=1&guid=6882be48-6626-5238-d3df-94e9f0a0019d | H18: =IFERROR(__xludf.DUMMYFUNCTION("""COMPUTED_VALUE"""),"Circulação / Corredores") -> Circulação / Corredores | I18: =IFERROR(__xludf.DUMMYFUNCTION("""COMPUTED_VALUE"""),"https://photos.google.com/search/2%C2%BAPav.-Corredor%20Central%20Setor%20B") -> https://photos.google.com/search/2%C2%BAPav.-Corredor%20Central%20Setor%20B
A19: =IFERROR(__xludf.DUMMYFUNCTION("""COMPUTED_VALUE"""),"2ºPav.-Corredor Circulação FME") -> 2ºPav.-Corredor Circulação FME | B19: =IFERROR(__xludf.DUMMYFUNCTION("""COMPUTED_VALUE"""),"2ºPav.") -> 2ºPav. | C19: =IFERROR(__xludf.DUMMYFUNCTION("""COMPUTED_VALUE"""),"Corredor Circulação FME") -> Corredor Circulação FME | D19: =IFERROR(__xludf.DUMMYFUNCTION("""COMPUTED_VALUE"""),"2ºPav.") -> 2ºPav. | E19: =IFERROR(__xludf.DUMMYFUNCTION("""COMPUTED_VALUE"""),"A") -> A | F19: =IFERROR(__xludf.DUMMYFUNCTION("""COMPUTED_VALUE"""),53.0) -> 53 | G19: =IFERROR(__xludf.DUMMYFUNCTION("""COMPUTED_VALUE"""),"https://myhub.autodesk360.com/ue29d95bb/g/projects/20210514412106331/data/dXJuOmFkc2sud2lwcHJvZDpmcy5mb2xkZXI6Y28ucU04eGNtQzdReXliS0NURmJQYUFTQQ/dXJuOmFkc2sud2lwcHJvZDpkbS5saW5lYWdlOlh4SzhZNFhHVEN5WDNPT29yLUd3WlE/viewer?version=1&commentId=urn:adsk.commen"&"ts:social.comment:40a82da47b2a42b3abfcf0cd35df5b10&showComments=1&guid=6882be48-6626-5238-d3df-94e9f0a0019d") -> https://myhub.autodesk360.com/ue29d95bb/g/projects/20210514412106331/data/dXJuOmFkc2sud2lwcHJvZDpmcy5mb2xkZXI6Y28ucU04eGNtQzdReXliS0NURmJQYUFTQQ/dXJuOmFkc2sud2lwcHJvZDpkbS5saW5lYWdlOlh4SzhZNFhHVEN5WDNPT29yLUd3WlE/viewer?version=1&commentId=urn:adsk.comments:social.comment:40a82da47b2a42b3abfcf0cd35df5b10&showComments=1&guid=6882be48-6626-5238-d3df-94e9f0a0019d | H19: =IFERROR(__xludf.DUMMYFUNCTION("""COMPUTED_VALUE"""),"Circulação / Corredores") -> Circulação / Corredores
A20: =IFERROR(__xludf.DUMMYFUNCTION("""COMPUTED_VALUE"""),"2ºPav.-Depósito") -> 2ºPav.-Depósito | B20: =IFERROR(__xludf.DUMMYFUNCTION("""COMPUTED_VALUE"""),"2ºPav.") -> 2ºPav. | C20: =IFERROR(__xludf.DUMMYFUNCTION("""COMPUTED_VALUE"""),"Depósito") -> Depósito | D20: =IFERROR(__xludf.DUMMYFUNCTION("""COMPUTED_VALUE"""),"2ºPav.") -> 2ºPav. | E20: =IFERROR(__xludf.DUMMYFUNCTION("""COMPUTED_VALUE"""),"A") -> A | G20: =IFERROR(__xludf.DUMMYFUNCTION("""COMPUTED_VALUE"""),"https://myhub.autodesk360.com/ue29d95bb/g/projects/20210514412106331/data/dXJuOmFkc2sud2lwcHJvZDpmcy5mb2xkZXI6Y28ucU04eGNtQzdReXliS0NURmJQYUFTQQ/dXJuOmFkc2sud2lwcHJvZDpkbS5saW5lYWdlOlh4SzhZNFhHVEN5WDNPT29yLUd3WlE/viewer?version=1&commentId=urn:adsk.commen"&"ts:social.comment:5f734b3fb3c045cfbd41782be16b890d&showComments=1&guid=6882be48-6626-5238-d3df-94e9f0a0019d") -> https://myhub.autodesk360.com/ue29d95bb/g/projects/20210514412106331/data/dXJuOmFkc2sud2lwcHJvZDpmcy5mb2xkZXI6Y28ucU04eGNtQzdReXliS0NURmJQYUFTQQ/dXJuOmFkc2sud2lwcHJvZDpkbS5saW5lYWdlOlh4SzhZNFhHVEN5WDNPT29yLUd3WlE/viewer?version=1&commentId=urn:adsk.comments:social.comment:5f734b3fb3c045cfbd41782be16b890d&showComments=1&guid=6882be48-6626-5238-d3df-94e9f0a0019d | H20: =IFERROR(__xludf.DUMMYFUNCTION("""COMPUTED_VALUE"""),"Depósito") -> Depósito
A21: =IFERROR(__xludf.DUMMYFUNCTION("""COMPUTED_VALUE"""),"2ºPav.-Depósito de Materiais e Equipamentos") -> 2ºPav.-Depósito de Materiais e Equipamentos | B21: =IFERROR(__xludf.DUMMYFUNCTION("""COMPUTED_VALUE"""),"2ºPav.") -> 2ºPav. | C21: =IFERROR(__xludf.DUMMYFUNCTION("""COMPUTED_VALUE"""),"Depósito de Materiais e Equipamentos") -> Depósito de Materiais e Equipamentos | D21: =IFERROR(__xludf.DUMMYFUNCTION("""COMPUTED_VALUE"""),"2ºPav.") -> 2ºPav. | E21: =IFERROR(__xludf.DUMMYFUNCTION("""COMPUTED_VALUE"""),"A") -> A | G21: =IFERROR(__xludf.DUMMYFUNCTION("""COMPUTED_VALUE"""),"https://myhub.autodesk360.com/ue29d95bb/g/projects/20210514412106331/data/dXJuOmFkc2sud2lwcHJvZDpmcy5mb2xkZXI6Y28ucU04eGNtQzdReXliS0NURmJQYUFTQQ/dXJuOmFkc2sud2lwcHJvZDpkbS5saW5lYWdlOlh4SzhZNFhHVEN5WDNPT29yLUd3WlE/viewer?version=1&commentId=urn:adsk.commen"&"ts:social.comment:cb61c77dd9914ef8afa1fba960bb0f25&showComments=1&guid=6882be48-6626-5238-d3df-94e9f0a0019d") -> https://myhub.autodesk360.com/ue29d95bb/g/projects/20210514412106331/data/dXJuOmFkc2sud2lwcHJvZDpmcy5mb2xkZXI6Y28ucU04eGNtQzdReXliS0NURmJQYUFTQQ/dXJuOmFkc2sud2lwcHJvZDpkbS5saW5lYWdlOlh4SzhZNFhHVEN5WDNPT29yLUd3WlE/viewer?version=1&commentId=urn:adsk.comments:social.comment:cb61c77dd9914ef8afa1fba960bb0f25&showComments=1&guid=6882be48-6626-5238-d3df-94e9f0a0019d | H21: =IFERROR(__xludf.DUMMYFUNCTION("""COMPUTED_VALUE"""),"Depósito") -> Depósito
A22: =IFERROR(__xludf.DUMMYFUNCTION("""COMPUTED_VALUE"""),"2ºPav.-Depósito Temporário Resíduos") -> 2ºPav.-Depósito Temporário Resíduos | B22: =IFERROR(__xludf.DUMMYFUNCTION("""COMPUTED_VALUE"""),"2ºPav.") -> 2ºPav. | C22: =IFERROR(__xludf.DUMMYFUNCTION("""COMPUTED_VALUE"""),"Depósito Temporário Resíduos") -> Depósito Temporário Resíduos | D22: =IFERROR(__xludf.DUMMYFUNCTION("""COMPUTED_VALUE"""),"2ºPav.") -> 2ºPav. | E22: =IFERROR(__xludf.DUMMYFUNCTION("""COMPUTED_VALUE"""),"A") -> A | G22: =IFERROR(__xludf.DUMMYFUNCTION("""COMPUTED_VALUE"""),"https://myhub.autodesk360.com/ue29d95bb/g/projects/20210514412106331/data/dXJuOmFkc2sud2lwcHJvZDpmcy5mb2xkZXI6Y28ucU04eGNtQzdReXliS0NURmJQYUFTQQ/dXJuOmFkc2sud2lwcHJvZDpkbS5saW5lYWdlOlh4SzhZNFhHVEN5WDNPT29yLUd3WlE/viewer?version=1&commentId=urn:adsk.commen"&"ts:social.comment:c38f19a6d2a44a469798a0c4f722223d&showComments=1&guid=6882be48-6626-5238-d3df-94e9f0a0019d") -> https://myhub.autodesk360.com/ue29d95bb/g/projects/20210514412106331/data/dXJuOmFkc2sud2lwcHJvZDpmcy5mb2xkZXI6Y28ucU04eGNtQzdReXliS0NURmJQYUFTQQ/dXJuOmFkc2sud2lwcHJvZDpkbS5saW5lYWdlOlh4SzhZNFhHVEN5WDNPT29yLUd3WlE/viewer?version=1&commentId=urn:adsk.comments:social.comment:c38f19a6d2a44a469798a0c4f722223d&showComments=1&guid=6882be48-6626-5238-d3df-94e9f0a0019d | H22: =IFERROR(__xludf.DUMMYFUNCTION("""COMPUTED_VALUE"""),"Outros") -> Outros
A23: =IFERROR(__xludf.DUMMYFUNCTION("""COMPUTED_VALUE"""),"2ºPav.-DML") -> 2ºPav.-DML | B23: =IFERROR(__xludf.DUMMYFUNCTION("""COMPUTED_VALUE"""),"2ºPav.") -> 2ºPav. | C23: =IFERROR(__xludf.DUMMYFUNCTION("""COMPUTED_VALUE"""),"DML") -> DML | D23: =IFERROR(__xludf.DUMMYFUNCTION("""COMPUTED_VALUE"""),"2ºPav.") -> 2ºPav. | E23: =IFERROR(__xludf.DUMMYFUNCTION("""COMPUTED_VALUE"""),"B") -> B | G23: =IFERROR(__xludf.DUMMYFUNCTION("""COMPUTED_VALUE"""),"https://myhub.autodesk360.com/ue29d95bb/g/projects/20210514412106331/data/dXJuOmFkc2sud2lwcHJvZDpmcy5mb2xkZXI6Y28ucU04eGNtQzdReXliS0NURmJQYUFTQQ/dXJuOmFkc2sud2lwcHJvZDpkbS5saW5lYWdlOlh4SzhZNFhHVEN5WDNPT29yLUd3WlE/viewer?version=1&commentId=urn:adsk.commen"&"ts:social.comment:84dfa0a6de464e138a15cfaf611ecaba&showComments=1&guid=6882be48-6626-5238-d3df-94e9f0a0019d") -> https://myhub.autodesk360.com/ue29d95bb/g/projects/20210514412106331/data/dXJuOmFkc2sud2lwcHJvZDpmcy5mb2xkZXI6Y28ucU04eGNtQzdReXliS0NURmJQYUFTQQ/dXJuOmFkc2sud2lwcHJvZDpkbS5saW5lYWdlOlh4SzhZNFhHVEN5WDNPT29yLUd3WlE/viewer?version=1&commentId=urn:adsk.comments:social.comment:84dfa0a6de464e138a15cfaf611ecaba&showComments=1&guid=6882be48-6626-5238-d3df-94e9f0a0019d | H23: =IFERROR(__xludf.DUMMYFUNCTION("""COMPUTED_VALUE"""),"Outros") -> Outros
A24: =IFERROR(__xludf.DUMMYFUNCTION("""COMPUTED_VALUE"""),"2ºPav.-Escada Prova de Fogo Setor B") -> 2ºPav.-Escada Prova de Fogo Setor B | B24: =IFERROR(__xludf.DUMMYFUNCTION("""COMPUTED_VALUE"""),"2ºPav.") -> 2ºPav. | C24: =IFERROR(__xludf.DUMMYFUNCTION("""COMPUTED_VALUE"""),"Escada Prova de Fogo Setor B") -> Escada Prova de Fogo Setor B | D24: =IFERROR(__xludf.DUMMYFUNCTION("""COMPUTED_VALUE"""),"2ºPav.") -> 2ºPav. | E24: =IFERROR(__xludf.DUMMYFUNCTION("""COMPUTED_VALUE"""),"B") -> B | F24: =IFERROR(__xludf.DUMMYFUNCTION("""COMPUTED_VALUE"""),67.0) -> 67 | G24: =IFERROR(__xludf.DUMMYFUNCTION("""COMPUTED_VALUE"""),"https://myhub.autodesk360.com/ue29d95bb/g/projects/20210514412106331/data/dXJuOmFkc2sud2lwcHJvZDpmcy5mb2xkZXI6Y28ucU04eGNtQzdReXliS0NURmJQYUFTQQ/dXJuOmFkc2sud2lwcHJvZDpkbS5saW5lYWdlOlh4SzhZNFhHVEN5WDNPT29yLUd3WlE/viewer?version=1&commentId=urn:adsk.commen"&"ts:social.comment:e19ad5dfb0924c6cb3f6176ce8f6b140&showComments=1&guid=6882be48-6626-5238-d3df-94e9f0a0019d") -> https://myhub.autodesk360.com/ue29d95bb/g/projects/20210514412106331/data/dXJuOmFkc2sud2lwcHJvZDpmcy5mb2xkZXI6Y28ucU04eGNtQzdReXliS0NURmJQYUFTQQ/dXJuOmFkc2sud2lwcHJvZDpkbS5saW5lYWdlOlh4SzhZNFhHVEN5WDNPT29yLUd3WlE/viewer?version=1&commentId=urn:adsk.comments:social.comment:e19ad5dfb0924c6cb3f6176ce8f6b140&showComments=1&guid=6882be48-6626-5238-d3df-94e9f0a0019d | H24: =IFERROR(__xludf.DUMMYFUNCTION("""COMPUTED_VALUE"""),"Escadas") -> Escadas
A25: =IFERROR(__xludf.DUMMYFUNCTION("""COMPUTED_VALUE"""),"2ºPav.-Guichê Atendimento FME") -> 2ºPav.-Guichê Atendimento FME | B25: =IFERROR(__xludf.DUMMYFUNCTION("""COMPUTED_VALUE"""),"2ºPav.") -> 2ºPav. | C25: =IFERROR(__xludf.DUMMYFUNCTION("""COMPUTED_VALUE"""),"Guichê Atendimento FME") -> Guichê Atendimento FME | D25: =IFERROR(__xludf.DUMMYFUNCTION("""COMPUTED_VALUE"""),"2ºPav.") -> 2ºPav. | E25: =IFERROR(__xludf.DUMMYFUNCTION("""COMPUTED_VALUE"""),"A") -> A | G25: =IFERROR(__xludf.DUMMYFUNCTION("""COMPUTED_VALUE"""),"https://myhub.autodesk360.com/ue29d95bb/g/projects/20210514412106331/data/dXJuOmFkc2sud2lwcHJvZDpmcy5mb2xkZXI6Y28ucU04eGNtQzdReXliS0NURmJQYUFTQQ/dXJuOmFkc2sud2lwcHJvZDpkbS5saW5lYWdlOlh4SzhZNFhHVEN5WDNPT29yLUd3WlE/viewer?version=1&commentId=urn:adsk.commen"&"ts:social.comment:662dfb8b50964380b3c7f176498ded32&showComments=1&guid=6882be48-6626-5238-d3df-94e9f0a0019d") -> https://myhub.autodesk360.com/ue29d95bb/g/projects/20210514412106331/data/dXJuOmFkc2sud2lwcHJvZDpmcy5mb2xkZXI6Y28ucU04eGNtQzdReXliS0NURmJQYUFTQQ/dXJuOmFkc2sud2lwcHJvZDpkbS5saW5lYWdlOlh4SzhZNFhHVEN5WDNPT29yLUd3WlE/viewer?version=1&commentId=urn:adsk.comments:social.comment:662dfb8b50964380b3c7f176498ded32&showComments=1&guid=6882be48-6626-5238-d3df-94e9f0a0019d | H25: =IFERROR(__xludf.DUMMYFUNCTION("""COMPUTED_VALUE"""),"Outros") -> Outros | I25: =IFERROR(__xludf.DUMMYFUNCTION("""COMPUTED_VALUE"""),"https://photos.google.com/search/2%C2%BAPav.-Guich%C3%AA%20Atendimento%20FME") -> https://photos.google.com/search/2%C2%BAPav.-Guich%C3%AA%20Atendimento%20FME
A26: =IFERROR(__xludf.DUMMYFUNCTION("""COMPUTED_VALUE"""),"2ºPav.-Hall Elevador Público") -> 2ºPav.-Hall Elevador Público | B26: =IFERROR(__xludf.DUMMYFUNCTION("""COMPUTED_VALUE"""),"2ºPav.") -> 2ºPav. | C26: =IFERROR(__xludf.DUMMYFUNCTION("""COMPUTED_VALUE"""),"Hall Elevador Público") -> Hall Elevador Público | D26: =IFERROR(__xludf.DUMMYFUNCTION("""COMPUTED_VALUE"""),"2ºPav.") -> 2ºPav. | E26: =IFERROR(__xludf.DUMMYFUNCTION("""COMPUTED_VALUE"""),"A") -> A | F26: =IFERROR(__xludf.DUMMYFUNCTION("""COMPUTED_VALUE"""),62.0) -> 62 | G26: =IFERROR(__xludf.DUMMYFUNCTION("""COMPUTED_VALUE"""),"https://myhub.autodesk360.com/ue29d95bb/g/projects/20210514412106331/data/dXJuOmFkc2sud2lwcHJvZDpmcy5mb2xkZXI6Y28ucU04eGNtQzdReXliS0NURmJQYUFTQQ/dXJuOmFkc2sud2lwcHJvZDpkbS5saW5lYWdlOlh4SzhZNFhHVEN5WDNPT29yLUd3WlE/viewer?version=1&commentId=urn:adsk.commen"&"ts:social.comment:5884c287db9648b39443a155542fd8c5&showComments=1&guid=6882be48-6626-5238-d3df-94e9f0a0019d") -> https://myhub.autodesk360.com/ue29d95bb/g/projects/20210514412106331/data/dXJuOmFkc2sud2lwcHJvZDpmcy5mb2xkZXI6Y28ucU04eGNtQzdReXliS0NURmJQYUFTQQ/dXJuOmFkc2sud2lwcHJvZDpkbS5saW5lYWdlOlh4SzhZNFhHVEN5WDNPT29yLUd3WlE/viewer?version=1&commentId=urn:adsk.comments:social.comment:5884c287db9648b39443a155542fd8c5&showComments=1&guid=6882be48-6626-5238-d3df-94e9f0a0019d | H26: =IFERROR(__xludf.DUMMYFUNCTION("""COMPUTED_VALUE"""),"Circulação / Corredores") -> Circulação / Corredores | I26: =IFERROR(__xludf.DUMMYFUNCTION("""COMPUTED_VALUE"""),"https://photos.google.com/search/2%C2%BAPav.-Hall%20Elevador%20P%C3%BAblico") -> https://photos.google.com/search/2%C2%BAPav.-Hall%20Elevador%20P%C3%BAblico
A27: =IFERROR(__xludf.DUMMYFUNCTION("""COMPUTED_VALUE"""),"2ºPav.-Hall Elevador Serviço") -> 2ºPav.-Hall Elevador Serviço | B27: =IFERROR(__xludf.DUMMYFUNCTION("""COMPUTED_VALUE"""),"2ºPav.") -> 2ºPav. | C27: =IFERROR(__xludf.DUMMYFUNCTION("""COMPUTED_VALUE"""),"Hall Elevador Serviço") -> Hall Elevador Serviço | D27: =IFERROR(__xludf.DUMMYFUNCTION("""COMPUTED_VALUE"""),"2ºPav.") -> 2ºPav. | E27: =IFERROR(__xludf.DUMMYFUNCTION("""COMPUTED_VALUE"""),"B") -> B | F27: =IFERROR(__xludf.DUMMYFUNCTION("""COMPUTED_VALUE"""),60.0) -> 60 | G27: =IFERROR(__xludf.DUMMYFUNCTION("""COMPUTED_VALUE"""),"https://myhub.autodesk360.com/ue29d95bb/g/projects/20210514412106331/data/dXJuOmFkc2sud2lwcHJvZDpmcy5mb2xkZXI6Y28ucU04eGNtQzdReXliS0NURmJQYUFTQQ/dXJuOmFkc2sud2lwcHJvZDpkbS5saW5lYWdlOlh4SzhZNFhHVEN5WDNPT29yLUd3WlE/viewer?version=1&commentId=urn:adsk.commen"&"ts:social.comment:ae4a173d9b514e4db71c242795dce105&showComments=1&guid=6882be48-6626-5238-d3df-94e9f0a0019d") -> https://myhub.autodesk360.com/ue29d95bb/g/projects/20210514412106331/data/dXJuOmFkc2sud2lwcHJvZDpmcy5mb2xkZXI6Y28ucU04eGNtQzdReXliS0NURmJQYUFTQQ/dXJuOmFkc2sud2lwcHJvZDpkbS5saW5lYWdlOlh4SzhZNFhHVEN5WDNPT29yLUd3WlE/viewer?version=1&commentId=urn:adsk.comments:social.comment:ae4a173d9b514e4db71c242795dce105&showComments=1&guid=6882be48-6626-5238-d3df-94e9f0a0019d | H27: =IFERROR(__xludf.DUMMYFUNCTION("""COMPUTED_VALUE"""),"Circulação / Corredores") -> Circulação / Corredores | I27: =IFERROR(__xludf.DUMMYFUNCTION("""COMPUTED_VALUE"""),"https://photos.google.com/search/2%C2%BAPav.-Hall%20Elevador%20Servi%C3%A7o") -> https://photos.google.com/search/2%C2%BAPav.-Hall%20Elevador%20Servi%C3%A7o
A28: =IFERROR(__xludf.DUMMYFUNCTION("""COMPUTED_VALUE"""),"2ºPav.-Lava Olhos e Chuveiro Emergência") -> 2ºPav.-Lava Olhos e Chuveiro Emergência | B28: =IFERROR(__xludf.DUMMYFUNCTION("""COMPUTED_VALUE"""),"2ºPav.") -> 2ºPav. | C28: =IFERROR(__xludf.DUMMYFUNCTION("""COMPUTED_VALUE"""),"Lava Olhos e Chuveiro Emergência") -> Lava Olhos e Chuveiro Emergência | D28: =IFERROR(__xludf.DUMMYFUNCTION("""COMPUTED_VALUE"""),"2ºPav.") -> 2ºPav. | E28: =IFERROR(__xludf.DUMMYFUNCTION("""COMPUTED_VALUE"""),"A") -> A | G28: =IFERROR(__xludf.DUMMYFUNCTION("""COMPUTED_VALUE"""),"https://myhub.autodesk360.com/ue29d95bb/g/projects/20210514412106331/data/dXJuOmFkc2sud2lwcHJvZDpmcy5mb2xkZXI6Y28ucU04eGNtQzdReXliS0NURmJQYUFTQQ/dXJuOmFkc2sud2lwcHJvZDpkbS5saW5lYWdlOlh4SzhZNFhHVEN5WDNPT29yLUd3WlE/viewer?version=1&commentId=urn:adsk.commen"&"ts:social.comment:5f734b3fb3c045cfbd41782be16b890d&showComments=1&guid=6882be48-6626-5238-d3df-94e9f0a0019d") -> https://myhub.autodesk360.com/ue29d95bb/g/projects/20210514412106331/data/dXJuOmFkc2sud2lwcHJvZDpmcy5mb2xkZXI6Y28ucU04eGNtQzdReXliS0NURmJQYUFTQQ/dXJuOmFkc2sud2lwcHJvZDpkbS5saW5lYWdlOlh4SzhZNFhHVEN5WDNPT29yLUd3WlE/viewer?version=1&commentId=urn:adsk.comments:social.comment:5f734b3fb3c045cfbd41782be16b890d&showComments=1&guid=6882be48-6626-5238-d3df-94e9f0a0019d | H28: =IFERROR(__xludf.DUMMYFUNCTION("""COMPUTED_VALUE"""),"Outros") -> Outros
